[2025-01-28T08:49:17.118+0000] {processor.py:186} INFO - Started process (PID=162) to work on /opt/airflow/dags/data_ingestion_dag.py
[2025-01-28T08:49:17.119+0000] {processor.py:914} INFO - Processing file /opt/airflow/dags/data_ingestion_dag.py for tasks to queue
[2025-01-28T08:49:17.121+0000] {logging_mixin.py:190} INFO - [2025-01-28T08:49:17.120+0000] {dagbag.py:588} INFO - Filling up the DagBag from /opt/airflow/dags/data_ingestion_dag.py
[2025-01-28T08:49:17.131+0000] {processor.py:925} INFO - DAG(s) 'dag_data_ingestion' retrieved from /opt/airflow/dags/data_ingestion_dag.py
[2025-01-28T08:49:17.395+0000] {logging_mixin.py:190} INFO - [2025-01-28T08:49:17.394+0000] {override.py:1911} INFO - Created Permission View: can delete on DAG:dag_data_ingestion
[2025-01-28T08:49:17.410+0000] {logging_mixin.py:190} INFO - [2025-01-28T08:49:17.410+0000] {override.py:1911} INFO - Created Permission View: can edit on DAG:dag_data_ingestion
[2025-01-28T08:49:17.422+0000] {logging_mixin.py:190} INFO - [2025-01-28T08:49:17.421+0000] {override.py:1911} INFO - Created Permission View: can read on DAG:dag_data_ingestion
[2025-01-28T08:49:17.433+0000] {logging_mixin.py:190} INFO - [2025-01-28T08:49:17.432+0000] {override.py:1911} INFO - Created Permission View: can delete on DAG Run:dag_data_ingestion
[2025-01-28T08:49:17.445+0000] {logging_mixin.py:190} INFO - [2025-01-28T08:49:17.444+0000] {override.py:1911} INFO - Created Permission View: menu access on DAG Run:dag_data_ingestion
[2025-01-28T08:49:17.457+0000] {logging_mixin.py:190} INFO - [2025-01-28T08:49:17.456+0000] {override.py:1911} INFO - Created Permission View: can read on DAG Run:dag_data_ingestion
[2025-01-28T08:49:17.464+0000] {logging_mixin.py:190} INFO - [2025-01-28T08:49:17.464+0000] {override.py:1911} INFO - Created Permission View: can create on DAG Run:dag_data_ingestion
[2025-01-28T08:49:17.465+0000] {logging_mixin.py:190} INFO - [2025-01-28T08:49:17.465+0000] {dag.py:3239} INFO - Sync 1 DAGs
[2025-01-28T08:49:17.483+0000] {logging_mixin.py:190} INFO - [2025-01-28T08:49:17.483+0000] {dag.py:3262} INFO - Creating ORM DAG for dag_data_ingestion
[2025-01-28T08:49:17.495+0000] {logging_mixin.py:190} INFO - [2025-01-28T08:49:17.494+0000] {dag.py:4180} INFO - Setting next_dagrun for dag_data_ingestion to None, run_after=None
[2025-01-28T08:49:17.511+0000] {processor.py:208} INFO - Processing /opt/airflow/dags/data_ingestion_dag.py took 0.398 seconds
[2025-01-28T08:49:48.800+0000] {processor.py:186} INFO - Started process (PID=173) to work on /opt/airflow/dags/data_ingestion_dag.py
[2025-01-28T08:49:48.801+0000] {processor.py:914} INFO - Processing file /opt/airflow/dags/data_ingestion_dag.py for tasks to queue
[2025-01-28T08:49:48.803+0000] {logging_mixin.py:190} INFO - [2025-01-28T08:49:48.803+0000] {dagbag.py:588} INFO - Filling up the DagBag from /opt/airflow/dags/data_ingestion_dag.py
[2025-01-28T08:49:48.815+0000] {processor.py:925} INFO - DAG(s) 'dag_data_ingestion' retrieved from /opt/airflow/dags/data_ingestion_dag.py
[2025-01-28T08:49:48.841+0000] {logging_mixin.py:190} INFO - [2025-01-28T08:49:48.840+0000] {dag.py:3239} INFO - Sync 1 DAGs
[2025-01-28T08:49:48.869+0000] {logging_mixin.py:190} INFO - [2025-01-28T08:49:48.868+0000] {dag.py:4180} INFO - Setting next_dagrun for dag_data_ingestion to None, run_after=None
[2025-01-28T08:49:48.874+0000] {processor.py:211} ERROR - Got an exception! Propagating...
Traceback (most recent call last):
  File "/home/airflow/.local/lib/python3.12/site-packages/airflow/dag_processing/processor.py", line 207, in _run_file_processor
    _handle_dag_file_processing()
  File "/home/airflow/.local/lib/python3.12/site-packages/airflow/dag_processing/processor.py", line 188, in _handle_dag_file_processing
    result: tuple[int, int, int] = dag_file_processor.process_file(
                                   ^^^^^^^^^^^^^^^^^^^^^^^^^^^^^^^^
  File "/home/airflow/.local/lib/python3.12/site-packages/airflow/utils/session.py", line 97, in wrapper
    return func(*args, session=session, **kwargs)
           ^^^^^^^^^^^^^^^^^^^^^^^^^^^^^^^^^^^^^^
  File "/home/airflow/.local/lib/python3.12/site-packages/airflow/dag_processing/processor.py", line 942, in process_file
    serialize_errors = DagFileProcessor.save_dag_to_db(
                       ^^^^^^^^^^^^^^^^^^^^^^^^^^^^^^^^
  File "/home/airflow/.local/lib/python3.12/site-packages/airflow/api_internal/internal_api_call.py", line 166, in wrapper
    return func(*args, **kwargs)
           ^^^^^^^^^^^^^^^^^^^^^
  File "/home/airflow/.local/lib/python3.12/site-packages/airflow/utils/session.py", line 97, in wrapper
    return func(*args, session=session, **kwargs)
           ^^^^^^^^^^^^^^^^^^^^^^^^^^^^^^^^^^^^^^
  File "/home/airflow/.local/lib/python3.12/site-packages/airflow/dag_processing/processor.py", line 982, in save_dag_to_db
    import_errors = DagBag._sync_to_db(dags=dags, processor_subdir=dag_directory, session=session)
                    ^^^^^^^^^^^^^^^^^^^^^^^^^^^^^^^^^^^^^^^^^^^^^^^^^^^^^^^^^^^^^^^^^^^^^^^^^^^^^^
  File "/home/airflow/.local/lib/python3.12/site-packages/airflow/utils/session.py", line 94, in wrapper
    return func(*args, **kwargs)
           ^^^^^^^^^^^^^^^^^^^^^
  File "/home/airflow/.local/lib/python3.12/site-packages/airflow/models/dagbag.py", line 708, in _sync_to_db
    for attempt in run_with_db_retries(logger=log):
                   ^^^^^^^^^^^^^^^^^^^^^^^^^^^^^^^
  File "/home/airflow/.local/lib/python3.12/site-packages/tenacity/__init__.py", line 443, in __iter__
    do = self.iter(retry_state=retry_state)
         ^^^^^^^^^^^^^^^^^^^^^^^^^^^^^^^^^^
  File "/home/airflow/.local/lib/python3.12/site-packages/tenacity/__init__.py", line 376, in iter
    result = action(retry_state)
             ^^^^^^^^^^^^^^^^^^^
  File "/home/airflow/.local/lib/python3.12/site-packages/tenacity/__init__.py", line 398, in <lambda>
    self._add_action_func(lambda rs: rs.outcome.result())
                                     ^^^^^^^^^^^^^^^^^^^
  File "/usr/local/lib/python3.12/concurrent/futures/_base.py", line 449, in result
    return self.__get_result()
           ^^^^^^^^^^^^^^^^^^^
  File "/usr/local/lib/python3.12/concurrent/futures/_base.py", line 401, in __get_result
    raise self._exception
  File "/home/airflow/.local/lib/python3.12/site-packages/airflow/models/dagbag.py", line 724, in _sync_to_db
    DAG.bulk_write_to_db(dags.values(), processor_subdir=processor_subdir, session=session)
  File "/home/airflow/.local/lib/python3.12/site-packages/airflow/utils/session.py", line 94, in wrapper
    return func(*args, **kwargs)
           ^^^^^^^^^^^^^^^^^^^^^
  File "/home/airflow/.local/lib/python3.12/site-packages/airflow/models/dag.py", line 3341, in bulk_write_to_db
    DagCode.bulk_sync_to_db(filelocs, session=session)
  File "/home/airflow/.local/lib/python3.12/site-packages/airflow/utils/session.py", line 94, in wrapper
    return func(*args, **kwargs)
           ^^^^^^^^^^^^^^^^^^^^^
  File "/home/airflow/.local/lib/python3.12/site-packages/airflow/models/dagcode.py", line 123, in bulk_sync_to_db
    os.path.getmtime(correct_maybe_zipped(fileloc)), tz=timezone.utc
    ^^^^^^^^^^^^^^^^^^^^^^^^^^^^^^^^^^^^^^^^^^^^^^^
  File "<frozen genericpath>", line 67, in getmtime
FileNotFoundError: [Errno 2] No such file or directory: '/opt/airflow/dags/data_ingestion_dag.py'
