[2025-01-26T14:33:26.696+0000] {local_task_job_runner.py:123} INFO - ::group::Pre task execution logs
[2025-01-26T14:33:26.713+0000] {taskinstance.py:2613} INFO - Dependencies all met for dep_context=non-requeueable deps ti=<TaskInstance: gcp_ingest.task_number_2 manual__2025-01-26T14:33:24.670752+00:00 [queued]>
[2025-01-26T14:33:26.721+0000] {taskinstance.py:2613} INFO - Dependencies all met for dep_context=requeueable deps ti=<TaskInstance: gcp_ingest.task_number_2 manual__2025-01-26T14:33:24.670752+00:00 [queued]>
[2025-01-26T14:33:26.722+0000] {taskinstance.py:2866} INFO - Starting attempt 1 of 2
[2025-01-26T14:33:26.732+0000] {taskinstance.py:2889} INFO - Executing <Task(BashOperator): task_number_2> on 2025-01-26 14:33:24.670752+00:00
[2025-01-26T14:33:26.739+0000] {standard_task_runner.py:104} INFO - Running: ['***', 'tasks', 'run', 'gcp_ingest', 'task_number_2', 'manual__2025-01-26T14:33:24.670752+00:00', '--job-id', '11', '--raw', '--subdir', 'DAGS_FOLDER/gcp_ingest_dag.py', '--cfg-path', '/tmp/tmpy9bscltc']
[2025-01-26T14:33:26.740+0000] {standard_task_runner.py:105} INFO - Job 11: Subtask task_number_2
[2025-01-26T14:33:26.742+0000] {logging_mixin.py:190} WARNING - /home/***/.local/lib/python3.12/site-packages/***/task/task_runner/standard_task_runner.py:70 DeprecationWarning: This process (pid=212) is multi-threaded, use of fork() may lead to deadlocks in the child.
[2025-01-26T14:33:26.742+0000] {standard_task_runner.py:72} INFO - Started process 213 to run task
[2025-01-26T14:33:26.776+0000] {task_command.py:467} INFO - Running <TaskInstance: gcp_ingest.task_number_2 manual__2025-01-26T14:33:24.670752+00:00 [running]> on host 3ba1a9b99dd9
[2025-01-26T14:33:26.843+0000] {taskinstance.py:3132} INFO - Exporting env vars: AIRFLOW_CTX_DAG_OWNER='***' AIRFLOW_CTX_DAG_ID='gcp_ingest' AIRFLOW_CTX_TASK_ID='task_number_2' AIRFLOW_CTX_EXECUTION_DATE='2025-01-26T14:33:24.670752+00:00' AIRFLOW_CTX_TRY_NUMBER='1' AIRFLOW_CTX_DAG_RUN_ID='manual__2025-01-26T14:33:24.670752+00:00'
[2025-01-26T14:33:26.844+0000] {taskinstance.py:731} INFO - ::endgroup::
[2025-01-26T14:33:26.855+0000] {subprocess.py:78} INFO - Tmp dir root location: /tmp
[2025-01-26T14:33:26.856+0000] {subprocess.py:88} INFO - Running command: ['/usr/bin/bash', '-c', 'head -n 10 /opt/***/dags/downloaded_data.csv']
[2025-01-26T14:33:26.866+0000] {subprocess.py:99} INFO - Output:
[2025-01-26T14:33:26.874+0000] {subprocess.py:106} INFO - head: cannot open '/opt/***/dags/downloaded_data.csv' for reading: No such file or directory
[2025-01-26T14:33:26.874+0000] {subprocess.py:110} INFO - Command exited with return code 1
[2025-01-26T14:33:26.886+0000] {taskinstance.py:3311} ERROR - Task failed with exception
Traceback (most recent call last):
  File "/home/airflow/.local/lib/python3.12/site-packages/airflow/models/taskinstance.py", line 767, in _execute_task
    result = _execute_callable(context=context, **execute_callable_kwargs)
             ^^^^^^^^^^^^^^^^^^^^^^^^^^^^^^^^^^^^^^^^^^^^^^^^^^^^^^^^^^^^^
  File "/home/airflow/.local/lib/python3.12/site-packages/airflow/models/taskinstance.py", line 733, in _execute_callable
    return ExecutionCallableRunner(
           ^^^^^^^^^^^^^^^^^^^^^^^^
  File "/home/airflow/.local/lib/python3.12/site-packages/airflow/utils/operator_helpers.py", line 252, in run
    return self.func(*args, **kwargs)
           ^^^^^^^^^^^^^^^^^^^^^^^^^^
  File "/home/airflow/.local/lib/python3.12/site-packages/airflow/models/baseoperator.py", line 422, in wrapper
    return func(self, *args, **kwargs)
           ^^^^^^^^^^^^^^^^^^^^^^^^^^^
  File "/home/airflow/.local/lib/python3.12/site-packages/airflow/operators/bash.py", line 276, in execute
    raise AirflowException(
airflow.exceptions.AirflowException: Bash command failed. The command returned a non-zero exit code 1.
[2025-01-26T14:33:26.899+0000] {taskinstance.py:1225} INFO - Marking task as UP_FOR_RETRY. dag_id=gcp_ingest, task_id=task_number_2, run_id=manual__2025-01-26T14:33:24.670752+00:00, execution_date=20250126T143324, start_date=20250126T143326, end_date=20250126T143326
[2025-01-26T14:33:26.915+0000] {taskinstance.py:340} INFO - ::group::Post task execution logs
[2025-01-26T14:33:26.916+0000] {standard_task_runner.py:124} ERROR - Failed to execute job 11 for task task_number_2 (Bash command failed. The command returned a non-zero exit code 1.; 213)
Traceback (most recent call last):
  File "/home/airflow/.local/lib/python3.12/site-packages/airflow/task/task_runner/standard_task_runner.py", line 117, in _start_by_fork
    ret = args.func(args, dag=self.dag)
          ^^^^^^^^^^^^^^^^^^^^^^^^^^^^^
  File "/home/airflow/.local/lib/python3.12/site-packages/airflow/cli/cli_config.py", line 49, in command
    return func(*args, **kwargs)
           ^^^^^^^^^^^^^^^^^^^^^
  File "/home/airflow/.local/lib/python3.12/site-packages/airflow/utils/cli.py", line 116, in wrapper
    return f(*args, **kwargs)
           ^^^^^^^^^^^^^^^^^^
  File "/home/airflow/.local/lib/python3.12/site-packages/airflow/cli/commands/task_command.py", line 483, in task_run
    task_return_code = _run_task_by_selected_method(args, _dag, ti)
                       ^^^^^^^^^^^^^^^^^^^^^^^^^^^^^^^^^^^^^^^^^^^^
  File "/home/airflow/.local/lib/python3.12/site-packages/airflow/cli/commands/task_command.py", line 256, in _run_task_by_selected_method
    return _run_raw_task(args, ti)
           ^^^^^^^^^^^^^^^^^^^^^^^
  File "/home/airflow/.local/lib/python3.12/site-packages/airflow/cli/commands/task_command.py", line 341, in _run_raw_task
    return ti._run_raw_task(
           ^^^^^^^^^^^^^^^^^
  File "/home/airflow/.local/lib/python3.12/site-packages/airflow/utils/session.py", line 97, in wrapper
    return func(*args, session=session, **kwargs)
           ^^^^^^^^^^^^^^^^^^^^^^^^^^^^^^^^^^^^^^
  File "/home/airflow/.local/lib/python3.12/site-packages/airflow/models/taskinstance.py", line 3005, in _run_raw_task
    return _run_raw_task(
           ^^^^^^^^^^^^^^
  File "/home/airflow/.local/lib/python3.12/site-packages/airflow/models/taskinstance.py", line 273, in _run_raw_task
    TaskInstance._execute_task_with_callbacks(
  File "/home/airflow/.local/lib/python3.12/site-packages/airflow/models/taskinstance.py", line 3159, in _execute_task_with_callbacks
    result = self._execute_task(context, task_orig)
             ^^^^^^^^^^^^^^^^^^^^^^^^^^^^^^^^^^^^^^
  File "/home/airflow/.local/lib/python3.12/site-packages/airflow/models/taskinstance.py", line 3183, in _execute_task
    return _execute_task(self, context, task_orig)
           ^^^^^^^^^^^^^^^^^^^^^^^^^^^^^^^^^^^^^^^
  File "/home/airflow/.local/lib/python3.12/site-packages/airflow/models/taskinstance.py", line 767, in _execute_task
    result = _execute_callable(context=context, **execute_callable_kwargs)
             ^^^^^^^^^^^^^^^^^^^^^^^^^^^^^^^^^^^^^^^^^^^^^^^^^^^^^^^^^^^^^
  File "/home/airflow/.local/lib/python3.12/site-packages/airflow/models/taskinstance.py", line 733, in _execute_callable
    return ExecutionCallableRunner(
           ^^^^^^^^^^^^^^^^^^^^^^^^
  File "/home/airflow/.local/lib/python3.12/site-packages/airflow/utils/operator_helpers.py", line 252, in run
    return self.func(*args, **kwargs)
           ^^^^^^^^^^^^^^^^^^^^^^^^^^
  File "/home/airflow/.local/lib/python3.12/site-packages/airflow/models/baseoperator.py", line 422, in wrapper
    return func(self, *args, **kwargs)
           ^^^^^^^^^^^^^^^^^^^^^^^^^^^
  File "/home/airflow/.local/lib/python3.12/site-packages/airflow/operators/bash.py", line 276, in execute
    raise AirflowException(
airflow.exceptions.AirflowException: Bash command failed. The command returned a non-zero exit code 1.
[2025-01-26T14:33:26.956+0000] {local_task_job_runner.py:266} INFO - Task exited with return code 1
[2025-01-26T14:33:26.976+0000] {taskinstance.py:3895} INFO - 0 downstream tasks scheduled from follow-on schedule check
[2025-01-26T14:33:26.977+0000] {local_task_job_runner.py:245} INFO - ::endgroup::
